<?xml version="1.0"?>
<robot xmlns:xacro="http://www.ros.org/wiki/xacro" name="dual_ur5">

  <!-- Include official UR macro from ur_description package -->
  <xacro:include filename="$(find ur_description)/urdf/ur_macro.xacro"/>

  <!-- ==================== WORLD & BASE ==================== -->

  <link name="world"/>

  <!-- Mounting table between the two arms -->
  <link name="base_platform">
    <visual>
      <geometry><box size="1.0 0.5 0.05"/></geometry>
      <material name="grey"><color rgba="0.5 0.5 0.5 1"/></material>
    </visual>
    <collision>
      <geometry><box size="1.0 0.5 0.05"/></geometry>
    </collision>
    <inertial>
      <mass value="20.0"/>
      <inertia ixx="0.1" ixy="0" ixz="0" iyy="0.1" iyz="0" izz="0.1"/>
    </inertial>
  </link>

  <joint name="world_to_platform" type="fixed">
    <parent link="world"/>
    <child link="base_platform"/>
    <origin xyz="0 0 -0.025" rpy="0 0 0"/>
  </joint>

  <!-- ==================== LEFT ARM (UR5) ==================== -->

    <xacro:ur_robot
    name="left"
    tf_prefix="left_"
    parent="world"
    joint_limits_parameters_file="$(find ur_description)/config/ur5/joint_limits.yaml"
    kinematics_parameters_file="$(find ur_description)/config/ur5/default_kinematics.yaml"
    physical_parameters_file="$(find ur_description)/config/ur5/physical_parameters.yaml"
    visual_parameters_file="$(find ur_description)/config/ur5/visual_parameters.yaml"
    generate_ros2_control_tag="false">
    <origin xyz="-0.35 0 0" rpy="0 0 1.5708"/>
  </xacro:ur_robot>

  <xacro:ur_robot
    name="right"
    tf_prefix="right_"
    parent="world"
    joint_limits_parameters_file="$(find ur_description)/config/ur5/joint_limits.yaml"
    kinematics_parameters_file="$(find ur_description)/config/ur5/default_kinematics.yaml"
    physical_parameters_file="$(find ur_description)/config/ur5/physical_parameters.yaml"
    visual_parameters_file="$(find ur_description)/config/ur5/visual_parameters.yaml"
    generate_ros2_control_tag="false">
    <origin xyz="0.35 0 0" rpy="0 0 ${pi + 1.5708}"/>
  </xacro:ur_robot>

  <!-- ==================== GRIPPER MACRO ==================== -->

  <xacro:macro name="simple_gripper" params="prefix parent">

    <link name="${prefix}gripper_base">
      <visual>
        <origin xyz="0 0 0.02" rpy="0 0 0"/>
        <geometry><cylinder radius="0.035" length="0.04"/></geometry>
        <material name="dark_grey"><color rgba="0.2 0.2 0.2 1"/></material>
      </visual>
      <collision>
        <origin xyz="0 0 0.02" rpy="0 0 0"/>
        <geometry><cylinder radius="0.035" length="0.04"/></geometry>
      </collision>
      <inertial>
        <mass value="0.3"/>
        <inertia ixx="0.001" ixy="0" ixz="0" iyy="0.001" iyz="0" izz="0.001"/>
      </inertial>
    </link>

    <joint name="${prefix}gripper_joint" type="fixed">
      <parent link="${parent}"/>
      <child link="${prefix}gripper_base"/>
      <origin xyz="0 0 0" rpy="0 0 0"/>
    </joint>

    <link name="${prefix}finger_left">
      <visual>
        <origin xyz="0 0 0.02" rpy="0 0 0"/>
        <geometry><box size="0.012 0.018 0.06"/></geometry>
        <material name="dark_grey"><color rgba="0.2 0.2 0.2 1"/></material>
      </visual>
      <collision>
        <origin xyz="0 0 0.02" rpy="0 0 0"/>
        <geometry><box size="0.012 0.018 0.06"/></geometry>
      </collision>
      <inertial>
        <mass value="0.05"/>
        <inertia ixx="0.0001" ixy="0" ixz="0" iyy="0.0001" iyz="0" izz="0.0001"/>
      </inertial>
    </link>

    <joint name="${prefix}finger_left_joint" type="prismatic">
      <parent link="${prefix}gripper_base"/>
      <child link="${prefix}finger_left"/>
      <origin xyz="-0.025 0 0.04" rpy="0 0 0"/>
      <axis xyz="1 0 0"/>
      <limit lower="-0.025" upper="0.0" effort="50" velocity="0.1"/>
      <dynamics damping="0.1" friction="0.1"/>
    </joint>

    <link name="${prefix}finger_right">
      <visual>
        <origin xyz="0 0 0.02" rpy="0 0 0"/>
        <geometry><box size="0.012 0.018 0.06"/></geometry>
        <material name="dark_grey"><color rgba="0.2 0.2 0.2 1"/></material>
      </visual>
      <collision>
        <origin xyz="0 0 0.02" rpy="0 0 0"/>
        <geometry><box size="0.012 0.018 0.06"/></geometry>
      </collision>
      <inertial>
        <mass value="0.05"/>
        <inertia ixx="0.0001" ixy="0" ixz="0" iyy="0.0001" iyz="0" izz="0.0001"/>
      </inertial>
    </link>

    <joint name="${prefix}finger_right_joint" type="prismatic">
      <parent link="${prefix}gripper_base"/>
      <child link="${prefix}finger_right"/>
      <origin xyz="0.025 0 0.04" rpy="0 0 0"/>
      <axis xyz="1 0 0"/>
      <limit lower="0.0" upper="0.025" effort="50" velocity="0.1"/>
      <dynamics damping="0.1" friction="0.1"/>
    </joint>

    <!-- TCP (Tool Center Point) — planning target for IK -->
    <link name="${prefix}tcp"/>
    <joint name="${prefix}tcp_joint" type="fixed">
      <parent link="${prefix}gripper_base"/>
      <child link="${prefix}tcp"/>
      <origin xyz="0 0 0.1" rpy="0 0 0"/>
    </joint>

  </xacro:macro>

  <!-- ==================== ATTACH GRIPPERS ==================== -->

  <xacro:simple_gripper prefix="left_" parent="left_tool0"/>
  <xacro:simple_gripper prefix="right_" parent="right_tool0"/>

</robot>